Workbook

Sheet Summary
A1: Qelvora: monthly net profit by monthly active users
A2: Net profit = platform revenue (after creator payouts, Stripe and Apple fees, plus ads if switched on) minus cloud, AI and vendor costs. Losses are red. Staffing, legal and one-time setup are not included.
A4: Net profit per month ($), ads on | B4: 0 users | C4: 100 users | D4: 1,000 users | E4: 10,000 users | F4: 100,000 users | G4: 1,000,000 users
A5: Conservative | B5: =Scenarios!B47 -> -362 | C5: =Scenarios!C47 -> -600.6001 | D5: =Scenarios!D47 -> -1329.036 | E5: =Scenarios!E47 -> -7854.71 | F5: =Scenarios!F47 -> -59278.1 | G5: =Scenarios!G47 -> -493660
A6: Base | B6: =Scenarios!B100 -> -362 | C6: =Scenarios!C100 -> -591.62072 | D6: =Scenarios!D100 -> -1240.2712 | E6: =Scenarios!E100 -> -6977.352 | F6: =Scenarios!F100 -> -51403.32 | G6: =Scenarios!G100 -> -416970.2
A7: Optimistic | B7: =Scenarios!B153 -> -362 | C7: =Scenarios!C153 -> -570.247 | D7: =Scenarios!D153 -> -1027.71 | E7: =Scenarios!E153 -> -4863.5 | F7: =Scenarios!F153 -> -31592 | G7: =Scenarios!G153 -> -221209
A8: Tuned | B8: =Scenarios!B206 -> -362 | C8: =Scenarios!C206 -> -536.5072 | D8: =Scenarios!D206 -> -689.136 | E8: =Scenarios!E206 -> -1466 | F8: =Scenarios!F206 -> 3458.2 | G8: =Scenarios!G206 -> 131645
A9: Your ladder | B9: =Scenarios!B259 -> -362 | C9: =Scenarios!C259 -> -573.25405 | D9: =Scenarios!D259 -> -1056.3105 | E9: =Scenarios!E259 -> -5134.8052 | F9: =Scenarios!F259 -> -32994.425 | G9: =Scenarios!G259 -> -232293.25
A10: Recommended | B10: =Scenarios!B312 -> -362 | C10: =Scenarios!C312 -> -552.84631 | D10: =Scenarios!D312 -> -852.08613 | E10: =Scenarios!E312 -> -3091.0913 | F10: =Scenarios!F312 -> -12804.179 | G10: =Scenarios!G312 -> -30096.788
A11: Recommended + tuned AI | B11: =Scenarios!B365 -> -362 | C11: =Scenarios!C365 -> -530.70167 | D11: =Scenarios!D365 -> -630.63973 | E11: =Scenarios!E365 -> -876.62728 | F11: =Scenarios!F365 -> 9340.4612 | G11: =Scenarios!G365 -> 191349.61
A13: Net profit per month ($), no ads | B13: 0 users | C13: 100 users | D13: 1,000 users | E13: 10,000 users | F13: 100,000 users | G13: 1,000,000 users
A14: Conservative | B14: =Scenarios!B48 -> -362 | C14: =Scenarios!C48 -> -603.3931 | D14: =Scenarios!D48 -> -1370.931 | E14: =Scenarios!E48 -> -8413.31 | F14: =Scenarios!F48 -> -66657.1 | G14: =Scenarios!G48 -> -590380
A15: Base | B15: =Scenarios!B101 -> -362 | C15: =Scenarios!C101 -> -594.20792 | D15: =Scenarios!D101 -> -1279.0792 | E15: =Scenarios!E101 -> -7494.792 | F15: =Scenarios!F101 -> -58164.92 | G15: =Scenarios!G101 -> -505458.2
A16: Optimistic | B16: =Scenarios!B154 -> -362 | C16: =Scenarios!C154 -> -572.599 | D16: =Scenarios!D154 -> -1062.99 | E16: =Scenarios!E154 -> -5333.9 | F16: =Scenarios!F154 -> -37648 | G16: =Scenarios!G154 -> -300289
A17: Tuned | B17: =Scenarios!B207 -> -362 | C17: =Scenarios!C207 -> -539.0944 | D17: =Scenarios!D207 -> -727.944 | E17: =Scenarios!E207 -> -1983.44 | F17: =Scenarios!F207 -> -3303.4 | G17: =Scenarios!G207 -> 43157
A18: Your ladder | B18: =Scenarios!B260 -> -362 | C18: =Scenarios!C260 -> -575.90005 | D18: =Scenarios!D260 -> -1096.0005 | E18: =Scenarios!E260 -> -5664.0052 | F18: =Scenarios!F260 -> -39932.425 | G18: =Scenarios!G260 -> -323133.25
A19: Recommended | B19: =Scenarios!B313 -> -362 | C19: =Scenarios!C313 -> -555.52171 | D19: =Scenarios!D313 -> -892.21713 | E19: =Scenarios!E313 -> -3626.1713 | F19: =Scenarios!F313 -> -19830.379 | G19: =Scenarios!G313 -> -122112.79
A20: Recommended + tuned AI | B20: =Scenarios!B366 -> -362 | C20: =Scenarios!C366 -> -533.37707 | D20: =Scenarios!D366 -> -670.77073 | E20: =Scenarios!E366 -> -1411.7073 | F20: =Scenarios!F366 -> 2314.2612 | G20: =Scenarios!G366 -> 99333.612
A22: Ad revenue per month ($), after network share | B22: 0 users | C22: 100 users | D22: 1,000 users | E22: 10,000 users | F22: 100,000 users | G22: 1,000,000 users
A23: Conservative | B23: =Scenarios!B23 -> 0 | C23: =Scenarios!C23 -> 2.793 | D23: =Scenarios!D23 -> 41.895 | E23: =Scenarios!E23 -> 558.6 | F23: =Scenarios!F23 -> 8379 | G23: =Scenarios!G23 -> 111720
A24: Base | B24: =Scenarios!B76 -> 0 | C24: =Scenarios!C76 -> 2.5872 | D24: =Scenarios!D76 -> 38.808 | E24: =Scenarios!E76 -> 517.44 | F24: =Scenarios!F76 -> 7761.6 | G24: =Scenarios!G76 -> 103488
A25: Optimistic | B25: =Scenarios!B129 -> 0 | C25: =Scenarios!C129 -> 2.352 | D25: =Scenarios!D129 -> 35.28 | E25: =Scenarios!E129 -> 470.4 | F25: =Scenarios!F129 -> 7056 | G25: =Scenarios!G129 -> 94080
A26: Tuned | B26: =Scenarios!B182 -> 0 | C26: =Scenarios!C182 -> 2.5872 | D26: =Scenarios!D182 -> 38.808 | E26: =Scenarios!E182 -> 517.44 | F26: =Scenarios!F182 -> 7761.6 | G26: =Scenarios!G182 -> 103488
A27: Your ladder | B27: =Scenarios!B235 -> 0 | C27: =Scenarios!C235 -> 2.646 | D27: =Scenarios!D235 -> 39.69 | E27: =Scenarios!E235 -> 529.2 | F27: =Scenarios!F235 -> 7938 | G27: =Scenarios!G235 -> 105840
A28: Recommended | B28: =Scenarios!B288 -> 0 | C28: =Scenarios!C288 -> 2.6754 | D28: =Scenarios!D288 -> 40.131 | E28: =Scenarios!E288 -> 535.08 | F28: =Scenarios!F288 -> 8026.2 | G28: =Scenarios!G288 -> 107016
A29: Recommended + tuned AI | B29: =Scenarios!B341 -> 0 | C29: =Scenarios!C341 -> 2.6754 | D29: =Scenarios!D341 -> 40.131 | E29: =Scenarios!E341 -> 535.08 | F29: =Scenarios!F341 -> 8026.2 | G29: =Scenarios!G341 -> 107016
A31: Net profit per year ($), ads on | B31: 0 users | C31: 100 users | D31: 1,000 users | E31: 10,000 users | F31: 100,000 users | G31: 1,000,000 users
A32: Conservative | B32: =Scenarios!B49 -> -4344 | C32: =Scenarios!C49 -> -7207.2012 | D32: =Scenarios!D49 -> -15948.432 | E32: =Scenarios!E49 -> -94256.52 | F32: =Scenarios!F49 -> -711337.2 | G32: =Scenarios!G49 -> -5923920
A33: Base | B33: =Scenarios!B102 -> -4344 | C33: =Scenarios!C102 -> -7099.4486 | D33: =Scenarios!D102 -> -14883.254 | E33: =Scenarios!E102 -> -83728.224 | F33: =Scenarios!F102 -> -616839.84 | G33: =Scenarios!G102 -> -5003642.4
A34: Optimistic | B34: =Scenarios!B155 -> -4344 | C34: =Scenarios!C155 -> -6842.964 | D34: =Scenarios!D155 -> -12332.52 | E34: =Scenarios!E155 -> -58362 | F34: =Scenarios!F155 -> -379104 | G34: =Scenarios!G155 -> -2654508
A35: Tuned | B35: =Scenarios!B208 -> -4344 | C35: =Scenarios!C208 -> -6438.0864 | D35: =Scenarios!D208 -> -8269.632 | E35: =Scenarios!E208 -> -17592 | F35: =Scenarios!F208 -> 41498.4 | G35: =Scenarios!G208 -> 1579740
A36: Your ladder | B36: =Scenarios!B261 -> -4344 | C36: =Scenarios!C261 -> -6879.0486 | D36: =Scenarios!D261 -> -12675.726 | E36: =Scenarios!E261 -> -61617.663 | F36: =Scenarios!F261 -> -395933.1 | G36: =Scenarios!G261 -> -2787519
A37: Recommended | B37: =Scenarios!B314 -> -4344 | C37: =Scenarios!C314 -> -6634.1558 | D37: =Scenarios!D314 -> -10225.034 | E37: =Scenarios!E314 -> -37093.095 | F37: =Scenarios!F314 -> -153650.15 | G37: =Scenarios!G314 -> -361161.46
A38: Recommended + tuned AI | B38: =Scenarios!B367 -> -4344 | C38: =Scenarios!C367 -> -6368.4201 | D38: =Scenarios!D367 -> -7567.6767 | E38: =Scenarios!E367 -> -10519.527 | F38: =Scenarios!F367 -> 112085.53 | G38: =Scenarios!G367 -> 2296195.3
A40: Platform revenue per month ($) | B40: 0 users | C40: 100 users | D40: 1,000 users | E40: 10,000 users | F40: 100,000 users | G40: 1,000,000 users
A41: Conservative | B41: =Scenarios!B25 -> 0 | C41: =Scenarios!C25 -> 11.9499 | D41: =Scenarios!D25 -> 133.464 | E41: =Scenarios!E25 -> 1474.29 | F41: =Scenarios!F25 -> 17220.9 | G41: =Scenarios!G25 -> 200139
A42: Base | B42: =Scenarios!B78 -> 0 | C42: =Scenarios!C78 -> 33.17928 | D42: =Scenarios!D78 -> 344.7288 | E42: =Scenarios!E78 -> 3576.648 | F42: =Scenarios!F78 -> 37345.68 | G42: =Scenarios!G78 -> 399328.8
A43: Optimistic | B43: =Scenarios!B131 -> 0 | C43: =Scenarios!C131 -> 68.553 | D43: =Scenarios!D131 -> 697.29 | E43: =Scenarios!E131 -> 7090.5 | F43: =Scenarios!F131 -> 71157 | G43: =Scenarios!G131 -> 735090
A44: Tuned | B44: =Scenarios!B184 -> 0 | C44: =Scenarios!C184 -> 51.0528 | D44: =Scenarios!D184 -> 523.464 | E44: =Scenarios!E184 -> 5364 | F44: =Scenarios!F184 -> 54967.2 | G44: =Scenarios!G184 -> 575544
A45: Your ladder | B45: =Scenarios!B237 -> 0 | C45: =Scenarios!C237 -> 35.345148 | D45: =Scenarios!D237 -> 366.68148 | E45: =Scenarios!E237 -> 3799.1148 | F45: =Scenarios!F237 -> 39553.775 | G45: =Scenarios!G237 -> 421997.75
...

Sheet Inputs
A1: Qelvora cost and revenue model: inputs
A2: Blue = editable input. Black = formula. Yellow = selector. Everything on Model, Tiers and Summary recalculates from this sheet.
A4: Scenario shown on the Model sheet | B4: Recommended | C4: Pick a scenario from the list. Ads can be switched off in the global assumptions.
A6: Scenario lever | B6: Conservative | C6: Base | D6: Optimistic | E6: Tuned | F6: Your ladder | G6: Recommended | H6: Recommended + tuned AI | I6: Active (feeds Model) | J6: Source / note
A7: Paid conversion (share of monthly users who pay) | B7: 0.05 | C7: 0.12 | D7: 0.2 | E7: 0.12 | F7: 0.1 | G7: 0.09 | H7: 0.09 | I7: =INDEX(B7:H7,MATCH($B$4,$B$6:$H$6,0)) -> 0.09 | J7: Assumption, not from the docs. Higher prices assumed to lower conversion (Your ladder 10%, Recommended 9%).
A8: Average spend per paying fan, $/month | B8: 6 | C8: 8 | D8: 10 | E8: 10 | F8: =B62*Inputs!$B$32 -> 10.31784 | G8: =E62*Inputs!$B$32 -> 14.388 | H8: =E62*Inputs!$B$32 -> 14.388 | I8: =INDEX(B8:H8,MATCH($B$4,$B$6:$H$6,0)) -> 14.388 | J8: First four are inputs. The ladder scenarios compute it from the ladder below: weighted price x memberships per payer.
A9: Accepted human-mode requests per user per month | B9: 0.005 | C9: 0.015 | D9: 0.03 | E9: 0.04 | F9: 0.015 | G9: 0.025 | H9: 0.025 | I9: =INDEX(B9:H9,MATCH($B$4,$B$6:$H$6,0)) -> 0.025 | J9: Assumption. Written reply, voice note or call; only accepted ones are charged (INV-16).
A10: Average human-mode price, $ | B10: 15 | C10: 20 | D10: 25 | E10: 25 | F10: 20 | G10: 30 | H10: 30 | I10: =INDEX(B10:H10,MATCH($B$4,$B$6:$H$6,0)) -> 30 | J10: Second Review uses a $25 written reply. Recommended assumes a mix of reply, voice note and call at about $30.
A11: Platform take on human modes | B11: 0.2 | C11: 0.2 | D11: 0.2 | E11: 0.2 | F11: 0.2 | G11: 0.25 | H11: 0.25 | I11: =INDEX(B11:H11,MATCH($B$4,$B$6:$H$6,0)) -> 0.25 | J11: Second Review illustrates 20%. Intro takes 30%. Recommended assumes 25%.
A12: AI cost per message, $ | B12: 0.014 | C12: 0.014 | D12: 0.014 | E12: 0.007 | F12: 0.014 | G12: 0.014 | H12: 0.007 | I12: =INDEX(B12:H12,MATCH($B$4,$B$6:$H$6,0)) -> 0.014 | J12: Estimate at Anthropic list prices (Sonnet 5.5 $2/$10, Haiku 4.5 $1/$5 per M tokens), 60% small / 40% large, incl. classifiers, memory, cache misses. Tuned = cheaper classifier model, better caching.
A13: AI messages per free or trial user per month | B13: 25 | C13: 25 | D13: 25 | E13: 10 | F13: 15 | G13: 15 | H13: 10 | I13: =INDEX(B13:H13,MATCH($B$4,$B$6:$H$6,0)) -> 15 | J13: Free first conversation is about 24 hours (D-26).
A14: AI messages per paying user per month | B14: 150 | C14: 150 | D14: 150 | E14: 150 | F14: =D62*Inputs!$B$32 -> 149.28 | G14: =G62*Inputs!$B$32 -> 149.28 | H14: =G62*Inputs!$B$32 -> 149.28 | I14: =INDEX(B14:H14,MATCH($B$4,$B$6:$H$6,0)) -> 149.28 | J14: Second Review membership case uses 150 messages. Ladder scenarios compute it from the messages used per tier.
A16: Global assumptions (same in every scenario) | B16: Value | C16: Source / note
A17: Creators as share of monthly users | B17: 0.01 | C17: Assumption: 1 creator per 100 fans.
A18: Minimum creators once any users exist | B18: 5 | C18: Pilot is 5 creators (Architecture workload model).
A19: Creator-side AI + verification, $ per creator per month | B19: 15 | C19: Interview, shadow evaluation, style cards, insights, ingestion, ID check. Estimate.
A20: Share of paying fans who pay on the web (Stripe) | B20: 0.65 | C20: Assumption. The rest pay through Apple in-app purchase (D-14).
A21: Stripe card rate | B21: 0.029 | C21: Source: stripe.com/pricing, 2.9% + $0.30 domestic cards.
A22: Stripe fixed fee per charge, $ | B22: 0.3 | C22: Source: stripe.com/pricing.
A23: Stripe Billing, % of subscription volume | B23: 0.007 | C23: Source: stripe.com/pricing, pay-as-you-go 0.7%.
A24: Apple fee, small-business rate | B24: 0.15 | C24: Apple Small Business Program (under $1M proceeds a year). Not re-verified here.
A25: Apple fee, rate above the threshold | B25: 0.25 | C25: Blend of the 15% and 30% rates in the Second Review. Assumption.
A26: Monthly users above which the higher Apple rate applies | B26: 10000 | C26: Assumption.
A27: Creator share of subscription revenue (after fees) | B27: 0.7 | C27: Second Review section 6, illustrative, not a decided price.
A28: AI voice notes per user per month | B28: 0.5 | C28: Slice 3 feature. Assumption.
... A36: Ad network or reseller share of ad revenue | B36: 0.3 | C36: Typical network or agency cut. Assumption.
A39: Fixed costs and ad rates by scale, $ per month | B39: 0 users | C39: 100 users | D39: 1,000 users | E39: 10,000 users | F39: 100,000 users | G39: 1,000,000 users | H39: Note
A40: Monthly active users (fans) | B40: 0 | C40: 100 | D40: 1000 | E40: 10000 | F40: 100000 | G40: 1000000 | H40: Edit these to model other sizes.
A41: Ad eCPM, $ per 1,000 impressions (rises as the audience grows) | B41: 0 | C41: 2 | D41: 3 | E41: 4 | F41: 6 | G41: 8 | H41: Assumption. Small audiences sell through networks at about $2 to $3; direct and premium sales at scale about $6 to $8. Chatbot display ads were about $10 eCPM per Koah Labs; ChatGPT ads $25 to $60 CPM (US, 2026), a different product.
A42: App compute (Fargate: interactive, generation, ingestion, trust worker, web) | B42: 75 | C42: 90 | D42: 150 | E42: 550 | F42: 3200 | G42: 17000 | H42: AWS list prices, approximate, not fetched.
A43: Load balancer, WAF, NAT and networking | B43: 60 | C43: 70 | D43: 90 | E43: 250 | F43: 900 | G43: 4500 | H43: Approximate.
A44: Postgres + pgvector (RDS, backups, replicas) | B44: 60 | C44: 60 | D44: 190 | E44: 530 | F44: 2800 | G44: 18000 | H44: Single-AZ at pilot; Multi-AZ and replicas as load grows.
A45: Redis / pub-sub (not in the design; added past one WebSocket node) | B45: 0 | C45: 0 | D45: 0 | E45: 100 | F45: 600 | G45: 2500 | H45: Recommendation, not in the architecture doc.
A46: Staging environment (separate stack, required by W8 isolation) | B46: 120 | C46: 150 | D46: 200 | E46: 500 | F46: 1500 | G46: 5000 | H46: infra/environments.json requires isolated staging.
A47: Object storage, CDN and data transfer | B47: 5 | C47: 5 | D47: 20 | E47: 200 | F47: 2000 | G47: 9000 | H47: Pantopus media storage may absorb part of this if reused.
A48: Monitoring, logs, error tracking | B48: 30 | C48: 50 | D48: 100 | E48: 400 | F48: 2500 | G48: 12000 | H48: Approximate.
A49: Secrets, KMS, security tooling, DR copies | B49: 10 | C49: 15 | D49: 30 | E49: 120 | F49: 700 | G49: 3500 | H49: Approximate.
A50: LiveKit (Ship $50 pilot; Scale $500 once calls and analytics are needed) | B50: 0 | C50: 50 | D50: 50 | E50: 500 | F50: 500 | G50: 500 | H50: Source: livekit.com/pricing.
A51: ElevenLabs plan floor (only after AI voice ships) | B51: 0 | C51: 0 | D51: 22 | E51: 99 | F51: 99 | G51: 299 | H51: Source: elevenlabs.io/pricing/api.
... A53: Ad operations: consent tool, brand-safety, ad-sales support (only if ads are on) | B53: 0 | C53: 0 | D53: 0 | E53: 0 | F53: 1000 | G53: 15000 | H53: Assumption. Direct ad sales at scale needs staff, which is not included.
...

Sheet Tiers
A1: Margin per membership, by tier (one fan, one creator, one month)
A2: Platform keeps its share of the price after card or Apple fees, then pays for the AI messages that member uses. Uses the AI cost per message of the scenario selected on Inputs!B4.
A3: ="AI cost per message used here: $"&TEXT(Inputs!I12,"0.000") -> AI cost per message used here: $0.014
A5: Your ladder | B5: Price | C5: Stripe fee (web) | D5: Platform share, paid on web | E5: Platform share, Apple at 15% | F5: AI messages used | G5: AI cost | H5: Margin, web | I5: Margin, Apple 15% | J5: Margin as % of price (web)
A6: Tier 1 | B6: =Inputs!B58 -> 5 | C6: =B6*(Inputs!$B$21+Inputs!$B$23)+Inputs!$B$22 -> 0.48 | D6: =(B6-C6)*(1-Inputs!$B$27) -> 1.356 | E6: =B6*(1-Inputs!$B$24)*(1-Inputs!$B$27) -> 1.275 | F6: =Inputs!D58 -> 80 | G6: =F6*Inputs!I12 -> 1.12 | H6: =D6-G6 -> 0.236 | I6: =E6-G6 -> 0.155 | J6: =IF(B6=0,0,H6/B6) -> 0.0472
A7: Tier 2 | B7: =Inputs!B59 -> 12.99 | C7: =B7*(Inputs!$B$21+Inputs!$B$23)+Inputs!$B$22 -> 0.76764 | D7: =(B7-C7)*(1-Inputs!$B$27) -> 3.666708 | E7: =B7*(1-Inputs!$B$24)*(1-Inputs!$B$27) -> 3.31245 | F7: =Inputs!D59 -> 180 | G7: =F7*Inputs!I12 -> 2.52 | H7: =D7-G7 -> 1.146708 | I7: =E7-G7 -> 0.79245 | J7: =IF(B7=0,0,H7/B7) -> 0.088276212
A8: Tier 3 | B8: =Inputs!B60 -> 20 | C8: =B8*(Inputs!$B$21+Inputs!$B$23)+Inputs!$B$22 -> 1.02 | D8: =(B8-C8)*(1-Inputs!$B$27) -> 5.694 | E8: =B8*(1-Inputs!$B$24)*(1-Inputs!$B$27) -> 5.1 | F8: =Inputs!D60 -> 320 | G8: =F8*Inputs!I12 -> 4.48 | H8: =D8-G8 -> 1.214 | I8: =E8-G8 -> 0.62 | J8: =IF(B8=0,0,H8/B8) -> 0.0607
A9: Tier 4 (top) | B9: =Inputs!B61 -> 49.99 | C9: =B9*(Inputs!$B$21+Inputs!$B$23)+Inputs!$B$22 -> 2.09964 | D9: =(B9-C9)*(1-Inputs!$B$27) -> 14.367108 | E9: =B9*(1-Inputs!$B$24)*(1-Inputs!$B$27) -> 12.74745 | F9: =Inputs!D61 -> 500 | G9: =F9*Inputs!I12 -> 7 | H9: =D9-G9 -> 7.367108 | I9: =E9-G9 -> 5.74745 | J9: =IF(B9=0,0,H9/B9) -> 0.14737163
A12: Recommended | B12: Price | C12: Stripe fee (web) | D12: Platform share, paid on web | E12: Platform share, Apple at 15% | F12: AI messages used | G12: AI cost | H12: Margin, web | I12: Margin, Apple 15% | J12: Margin as % of price (web)
A13: Tier 1 | B13: =Inputs!E58 -> 6.99 | C13: =B13*(Inputs!$B$21+Inputs!$B$23)+Inputs!$B$22 -> 0.55164 | D13: =(B13-C13)*(1-Inputs!$B$27) -> 1.931508 | E13: =B13*(1-Inputs!$B$24)*(1-Inputs!$B$27) -> 1.78245 | F13: =Inputs!G58 -> 80 | G13: =F13*Inputs!I12 -> 1.12 | H13: =D13-G13 -> 0.811508 | I13: =E13-G13 -> 0.66245 | J13: =IF(B13=0,0,H13/B13) -> 0.11609557
A14: Tier 2 | B14: =Inputs!E59 -> 14.99 | C14: =B14*(Inputs!$B$21+Inputs!$B$23)+Inputs!$B$22 -> 0.83964 | D14: =(B14-C14)*(1-Inputs!$B$27) -> 4.245108 | E14: =B14*(1-Inputs!$B$24)*(1-Inputs!$B$27) -> 3.82245 | F14: =Inputs!G59 -> 180 | G14: =F14*Inputs!I12 -> 2.52 | H14: =D14-G14 -> 1.725108 | I14: =E14-G14 -> 1.30245 | J14: =IF(B14=0,0,H14/B14) -> 0.11508392
A15: Tier 3 | B15: =Inputs!E60 -> 29.99 | C15: =B15*(Inputs!$B$21+Inputs!$B$23)+Inputs!$B$22 -> 1.37964 | D15: =(B15-C15)*(1-Inputs!$B$27) -> 8.583108 | E15: =B15*(1-Inputs!$B$24)*(1-Inputs!$B$27) -> 7.64745 | F15: =Inputs!G60 -> 320 | G15: =F15*Inputs!I12 -> 4.48 | H15: =D15-G15 -> 4.103108 | I15: =E15-G15 -> 3.16745 | J15: =IF(B15=0,0,H15/B15) -> 0.13681587
A16: Tier 4 (top) | B16: =Inputs!E61 -> 79.99 | C16: =B16*(Inputs!$B$21+Inputs!$B$23)+Inputs!$B$22 -> 3.17964 | D16: =(B16-C16)*(1-Inputs!$B$27) -> 23.043108 | E16: =B16*(1-Inputs!$B$24)*(1-Inputs!$B$27) -> 20.39745 | F16: =Inputs!G61 -> 500 | G16: =F16*Inputs!I12 -> 7 | H16: =D16-G16 -> 16.043108 | I16: =E16-G16 -> 13.39745 | J16: =IF(B16=0,0,H16/B16) -> 0.20056392
A19: Reading it: a tier whose margin is near zero or negative loses money on every member who uses their allowance, no matter how many join. Human-mode revenue and ads are not included here.

Sheet Model
A1: Model: selected scenario
A2: ="Scenario: "&Inputs!B4 -> Scenario: Recommended
A3: Selected scenario (change it on Inputs!B4) | B3: 0 users | C3: 100 users | D3: 1,000 users | E3: 10,000 users | F3: 100,000 users | G3: 1,000,000 users
A4: Users
A5: Monthly active users | B5: =Inputs!B$40 -> 0 | C5: =Inputs!C$40 -> 100 | D5: =Inputs!D$40 -> 1000 | E5: =Inputs!E$40 -> 10000 | F5: =Inputs!F$40 -> 100000 | G5: =Inputs!G$40 -> 1000000
A6: Creators | B6: =IF(B5=0,0,MAX(Inputs!$B$18,ROUND(B5*Inputs!$B$17,0))) -> 0 | C6: =IF(C5=0,0,MAX(Inputs!$B$18,ROUND(C5*Inputs!$B$17,0))) -> 5 | D6: =IF(D5=0,0,MAX(Inputs!$B$18,ROUND(D5*Inputs!$B$17,0))) -> 10 | E6: =IF(E5=0,0,MAX(Inputs!$B$18,ROUND(E5*Inputs!$B$17,0))) -> 100 | F6: =IF(F5=0,0,MAX(Inputs!$B$18,ROUND(F5*Inputs!$B$17,0))) -> 1000 | G6: =IF(G5=0,0,MAX(Inputs!$B$18,ROUND(G5*Inputs!$B$17,0))) -> 10000
A7: Paying fans | B7: =B5*Inputs!$I$7 -> 0 | C7: =C5*Inputs!$I$7 -> 9 | D7: =D5*Inputs!$I$7 -> 90 | E7: =E5*Inputs!$I$7 -> 900 | F7: =F5*Inputs!$I$7 -> 9000 | G7: =G5*Inputs!$I$7 -> 90000
A8: Non-paying fans (see ads) | B8: =B5-B7 -> 0 | C8: =C5-C7 -> 91 | D8: =D5-D7 -> 910 | E8: =E5-E7 -> 9100 | F8: =F5-F7 -> 91000 | G8: =G5-G7 -> 910000
A9: Revenue (what the platform keeps)
A10: Subscription spend by fans (gross) | B10: =B7*Inputs!$I$8 -> 0 | C10: =C7*Inputs!$I$8 -> 129.492 | D10: =D7*Inputs!$I$8 -> 1294.92 | E10: =E7*Inputs!$I$8 -> 12949.2 | F10: =F7*Inputs!$I$8 -> 129492 | G10: =G7*Inputs!$I$8 -> 1294920
A11: of which paid on web (Stripe) | B11: =B10*Inputs!$B$20 -> 0 | C11: =C10*Inputs!$B$20 -> 84.1698 | D11: =D10*Inputs!$B$20 -> 841.698 | E11: =E10*Inputs!$B$20 -> 8416.98 | F11: =F10*Inputs!$B$20 -> 84169.8 | G11: =G10*Inputs!$B$20 -> 841698
A12: of which paid through Apple in-app purchase | B12: =B10-B11 -> 0 | C12: =C10-C11 -> 45.3222 | D12: =D10-D11 -> 453.222 | E12: =E10-E11 -> 4532.22 | F12: =F10-F11 -> 45322.2 | G12: =G10-G11 -> 453222
A13: Stripe fees on subscriptions | B13: =B7*Inputs!$B$20*Inputs!$B$22+B11*(Inputs!$B$21+Inputs!$B$23) -> 0 | C13: =C7*Inputs!$B$20*Inputs!$B$22+C11*(Inputs!$B$21+Inputs!$B$23) -> 4.7851128 | D13: =D7*Inputs!$B$20*Inputs!$B$22+D11*(Inputs!$B$21+Inputs!$B$23) -> 47.851128 | E13: =E7*Inputs!$B$20*Inputs!$B$22+E11*(Inputs!$B$21+Inputs!$B$23) -> 478.51128 | F13: =F7*Inputs!$B$20*Inputs!$B$22+F11*(Inputs!$B$21+Inputs!$B$23) -> 4785.1128 | G13: =G7*Inputs!$B$20*Inputs!$B$22+G11*(Inputs!$B$21+Inputs!$B$23) -> 47851.128
A14: Apple fees on in-app purchases | B14: =B12*IF(B5>Inputs!$B$26,Inputs!$B$25,Inputs!$B$24) -> 0 | C14: =C12*IF(C5>Inputs!$B$26,Inputs!$B$25,Inputs!$B$24) -> 6.79833 | D14: =D12*IF(D5>Inputs!$B$26,Inputs!$B$25,Inputs!$B$24) -> 67.9833 | E14: =E12*IF(E5>Inputs!$B$26,Inputs!$B$25,Inputs!$B$24) -> 679.833 | F14: =F12*IF(F5>Inputs!$B$26,Inputs!$B$25,Inputs!$B$24) -> 11330.55 | G14: =G12*IF(G5>Inputs!$B$26,Inputs!$B$25,Inputs!$B$24) -> 113305.5
A15: Subscription revenue after fees | B15: =B10-B13-B14 -> 0 | C15: =C10-C13-C14 -> 117.90856 | D15: =D10-D13-D14 -> 1179.0856 | E15: =E10-E13-E14 -> 11790.856 | F15: =F10-F13-F14 -> 113376.34 | G15: =G10-G13-G14 -> 1133763.4
A16: paid out to creators | B16: =B15*Inputs!$B$27 -> 0 | C16: =C15*Inputs!$B$27 -> 82.53599 | D16: =D15*Inputs!$B$27 -> 825.3599 | E16: =E15*Inputs!$B$27 -> 8253.599 | F16: =F15*Inputs!$B$27 -> 79363.436 | G16: =G15*Inputs!$B$27 -> 793634.36
A17: Platform subscription revenue | B17: =B15-B16 -> 0 | C17: =C15-C16 -> 35.372567 | D17: =D15-D16 -> 353.72567 | E17: =E15-E16 -> 3537.2567 | F17: =F15-F16 -> 34012.901 | G17: =G15-G16 -> 340129.01
A18: Accepted human-mode requests | B18: =B5*Inputs!$I$9 -> 0 | C18: =C5*Inputs!$I$9 -> 2.5 | D18: =D5*Inputs!$I$9 -> 25 | E18: =E5*Inputs!$I$9 -> 250 | F18: =F5*Inputs!$I$9 -> 2500 | G18: =G5*Inputs!$I$9 -> 25000
A19: Human-mode spend by fans (gross) | B19: =B18*Inputs!$I$10 -> 0 | C19: =C18*Inputs!$I$10 -> 75 | D19: =D18*Inputs!$I$10 -> 750 | E19: =E18*Inputs!$I$10 -> 7500 | F19: =F18*Inputs!$I$10 -> 75000 | G19: =G18*Inputs!$I$10 -> 750000
A20: Stripe fees on human modes | B20: =B18*(Inputs!$B$21*Inputs!$I$10+Inputs!$B$22) -> 0 | C20: =C18*(Inputs!$B$21*Inputs!$I$10+Inputs!$B$22) -> 2.925 | D20: =D18*(Inputs!$B$21*Inputs!$I$10+Inputs!$B$22) -> 29.25 | E20: =E18*(Inputs!$B$21*Inputs!$I$10+Inputs!$B$22) -> 292.5 | F20: =F18*(Inputs!$B$21*Inputs!$I$10+Inputs!$B$22) -> 2925 | G20: =G18*(Inputs!$B$21*Inputs!$I$10+Inputs!$B$22) -> 29250
A21: paid out to creators | B21: =B19*(1-Inputs!$I$11) -> 0 | C21: =C19*(1-Inputs!$I$11) -> 56.25 | D21: =D19*(1-Inputs!$I$11) -> 562.5 | E21: =E19*(1-Inputs!$I$11) -> 5625 | F21: =F19*(1-Inputs!$I$11) -> 56250 | G21: =G19*(1-Inputs!$I$11) -> 562500
A22: Platform human-mode revenue (take minus card fee) | B22: =B19*Inputs!$I$11-B20 -> 0 | C22: =C19*Inputs!$I$11-C20 -> 15.825 | D22: =D19*Inputs!$I$11-D20 -> 158.25 | E22: =E19*Inputs!$I$11-E20 -> 1582.5 | F22: =F19*Inputs!$I$11-F20 -> 15825 | G22: =G19*Inputs!$I$11-G20 -> 158250
A23: Ad revenue to the platform (non-paying fans only, after network share) | B23: =Inputs!$B$33*B8*Inputs!$B$34*Inputs!$B$35*Inputs!B$41/1000*(1-Inputs!$B$36) -> 0 | C23: =Inputs!$B$33*C8*Inputs!$B$34*Inputs!$B$35*Inputs!C$41/1000*(1-Inputs!$B$36) -> 2.6754 | D23: =Inputs!$B$33*D8*Inputs!$B$34*Inputs!$B$35*Inputs!D$41/1000*(1-Inputs!$B$36) -> 40.131 | E23: =Inputs!$B$33*E8*Inputs!$B$34*Inputs!$B$35*Inputs!E$41/1000*(1-Inputs!$B$36) -> 535.08 | F23: =Inputs!$B$33*F8*Inputs!$B$34*Inputs!$B$35*Inputs!F$41/1000*(1-Inputs!$B$36) -> 8026.2 | G23: =Inputs!$B$33*G8*Inputs!$B$34*Inputs!$B$35*Inputs!G$41/1000*(1-Inputs!$B$36) -> 107016
A24: Total fan spend (gross, excluding ads) | B24: =B10+B19 -> 0 | C24: =C10+C19 -> 204.492 | D24: =D10+D19 -> 2044.92 | E24: =E10+E19 -> 20449.2 | F24: =F10+F19 -> 204492 | G24: =G10+G19 -> 2044920
A25: PLATFORM REVENUE | B25: =B17+B22+B23 -> 0 | C25: =C17+C22+C23 -> 53.872967 | D25: =D17+D22+D23 -> 552.10667 | E25: =E17+E22+E23 -> 5654.8367 | F25: =F17+F22+F23 -> 57864.101 | G25: =G17+G22+G23 -> 605395.01
A26: Costs
A27: AI messages per month (fans) | B27: =B5*((1-Inputs!$I$7)*Inputs!$I$13+Inputs!$I$7*Inputs!$I$14) -> 0 | C27: =C5*((1-Inputs!$I$7)*Inputs!$I$13+Inputs!$I$7*Inputs!$I$14) -> 2708.52 | D27: =D5*((1-Inputs!$I$7)*Inputs!$I$13+Inputs!$I$7*Inputs!$I$14) -> 27085.2 | E27: =E5*((1-Inputs!$I$7)*Inputs!$I$13+Inputs!$I$7*Inputs!$I$14) -> 270852 | F27: =F5*((1-Inputs!$I$7)*Inputs!$I$13+Inputs!$I$7*Inputs!$I$14) -> 2708520 | G27: =G5*((1-Inputs!$I$7)*Inputs!$I$13+Inputs!$I$7*Inputs!$I$14) -> 27085200
A28: Fan AI (model calls) | B28: =B27*Inputs!$I$12 -> 0 | C28: =C27*Inputs!$I$12 -> 37.91928 | D28: =D27*Inputs!$I$12 -> 379.1928 | E28: =E27*Inputs!$I$12 -> 3791.928 | F28: =F27*Inputs!$I$12 -> 37919.28 | G28: =G27*Inputs!$I$12 -> 379192.8
A29: Creator-side AI and verification | B29: =B6*Inputs!$B$19 -> 0 | C29: =C6*Inputs!$B$19 -> 75 | D29: =D6*Inputs!$B$19 -> 150 | E29: =E6*Inputs!$B$19 -> 1500 | F29: =F6*Inputs!$B$19 -> 15000 | G29: =G6*Inputs!$B$19 -> 150000
A30: AI voice | B30: =B5*Inputs!$B$28*Inputs!$B$29/1000*Inputs!$B$30 -> 0 | C30: =C5*Inputs!$B$28*Inputs!$B$29/1000*Inputs!$B$30 -> 1.6 | D30: =D5*Inputs!$B$28*Inputs!$B$29/1000*Inputs!$B$30 -> 16 | E30: =E5*Inputs!$B$28*Inputs!$B$29/1000*Inputs!$B$30 -> 160 | F30: =F5*Inputs!$B$28*Inputs!$B$29/1000*Inputs!$B$30 -> 1600 | G30: =G5*Inputs!$B$28*Inputs!$B$29/1000*Inputs!$B$30 -> 16000
A31: Moderation and image scanning | B31: =B5*Inputs!$B$31 -> 0 | C31: =C5*Inputs!$B$31 -> 0.2 | D31: =D5*Inputs!$B$31 -> 2 | E31: =E5*Inputs!$B$31 -> 20 | F31: =F5*Inputs!$B$31 -> 200 | G31: =G5*Inputs!$B$31 -> 2000
A32: App compute (Fargate: interactive, generation, ingestion, trust worker, web) | B32: =Inputs!B$42 -> 75 | C32: =Inputs!C$42 -> 90 | D32: =Inputs!D$42 -> 150 | E32: =Inputs!E$42 -> 550 | F32: =Inputs!F$42 -> 3200 | G32: =Inputs!G$42 -> 17000
A33: Load balancer, WAF, NAT and networking | B33: =Inputs!B$43 -> 60 | C33: =Inputs!C$43 -> 70 | D33: =Inputs!D$43 -> 90 | E33: =Inputs!E$43 -> 250 | F33: =Inputs!F$43 -> 900 | G33: =Inputs!G$43 -> 4500
A34: Postgres + pgvector (RDS, backups, replicas) | B34: =Inputs!B$44 -> 60 | C34: =Inputs!C$44 -> 60 | D34: =Inputs!D$44 -> 190 | E34: =Inputs!E$44 -> 530 | F34: =Inputs!F$44 -> 2800 | G34: =Inputs!G$44 -> 18000
A35: Redis / pub-sub (not in the design; added past one WebSocket node) | B35: =Inputs!B$45 -> 0 | C35: =Inputs!C$45 -> 0 | D35: =Inputs!D$45 -> 0 | E35: =Inputs!E$45 -> 100 | F35: =Inputs!F$45 -> 600 | G35: =Inputs!G$45 -> 2500
A36: Staging environment (separate stack, required by W8 isolation) | B36: =Inputs!B$46 -> 120 | C36: =Inputs!C$46 -> 150 | D36: =Inputs!D$46 -> 200 | E36: =Inputs!E$46 -> 500 | F36: =Inputs!F$46 -> 1500 | G36: =Inputs!G$46 -> 5000
A37: Object storage, CDN and data transfer | B37: =Inputs!B$47 -> 5 | C37: =Inputs!C$47 -> 5 | D37: =Inputs!D$47 -> 20 | E37: =Inputs!E$47 -> 200 | F37: =Inputs!F$47 -> 2000 | G37: =Inputs!G$47 -> 9000
A38: Monitoring, logs, error tracking | B38: =Inputs!B$48 -> 30 | C38: =Inputs!C$48 -> 50 | D38: =Inputs!D$48 -> 100 | E38: =Inputs!E$48 -> 400 | F38: =Inputs!F$48 -> 2500 | G38: =Inputs!G$48 -> 12000
A39: Secrets, KMS, security tooling, DR copies | B39: =Inputs!B$49 -> 10 | C39: =Inputs!C$49 -> 15 | D39: =Inputs!D$49 -> 30 | E39: =Inputs!E$49 -> 120 | F39: =Inputs!F$49 -> 700 | G39: =Inputs!G$49 -> 3500
A40: LiveKit (Ship $50 pilot; Scale $500 once calls and analytics are needed) | B40: =Inputs!B$50 -> 0 | C40: =Inputs!C$50 -> 50 | D40: =Inputs!D$50 -> 50 | E40: =Inputs!E$50 -> 500 | F40: =Inputs!F$50 -> 500 | G40: =Inputs!G$50 -> 500
...

Sheet Scenarios
A1: Scenarios: all side by side (same formulas as Model, each tied to its own scenario column)
A3: Conservative scenario | B3: 0 users | C3: 100 users | D3: 1,000 users | E3: 10,000 users | F3: 100,000 users | G3: 1,000,000 users
A4: Users
A5: Monthly active users | B5: =Inputs!B$40 -> 0 | C5: =Inputs!C$40 -> 100 | D5: =Inputs!D$40 -> 1000 | E5: =Inputs!E$40 -> 10000 | F5: =Inputs!F$40 -> 100000 | G5: =Inputs!G$40 -> 1000000
A6: Creators | B6: =IF(B5=0,0,MAX(Inputs!$B$18,ROUND(B5*Inputs!$B$17,0))) -> 0 | C6: =IF(C5=0,0,MAX(Inputs!$B$18,ROUND(C5*Inputs!$B$17,0))) -> 5 | D6: =IF(D5=0,0,MAX(Inputs!$B$18,ROUND(D5*Inputs!$B$17,0))) -> 10 | E6: =IF(E5=0,0,MAX(Inputs!$B$18,ROUND(E5*Inputs!$B$17,0))) -> 100 | F6: =IF(F5=0,0,MAX(Inputs!$B$18,ROUND(F5*Inputs!$B$17,0))) -> 1000 | G6: =IF(G5=0,0,MAX(Inputs!$B$18,ROUND(G5*Inputs!$B$17,0))) -> 10000
A7: Paying fans | B7: =B5*Inputs!$B$7 -> 0 | C7: =C5*Inputs!$B$7 -> 5 | D7: =D5*Inputs!$B$7 -> 50 | E7: =E5*Inputs!$B$7 -> 500 | F7: =F5*Inputs!$B$7 -> 5000 | G7: =G5*Inputs!$B$7 -> 50000
A8: Non-paying fans (see ads) | B8: =B5-B7 -> 0 | C8: =C5-C7 -> 95 | D8: =D5-D7 -> 950 | E8: =E5-E7 -> 9500 | F8: =F5-F7 -> 95000 | G8: =G5-G7 -> 950000
A9: Revenue (what the platform keeps)
A10: Subscription spend by fans (gross) | B10: =B7*Inputs!$B$8 -> 0 | C10: =C7*Inputs!$B$8 -> 30 | D10: =D7*Inputs!$B$8 -> 300 | E10: =E7*Inputs!$B$8 -> 3000 | F10: =F7*Inputs!$B$8 -> 30000 | G10: =G7*Inputs!$B$8 -> 300000
A11: of which paid on web (Stripe) | B11: =B10*Inputs!$B$20 -> 0 | C11: =C10*Inputs!$B$20 -> 19.5 | D11: =D10*Inputs!$B$20 -> 195 | E11: =E10*Inputs!$B$20 -> 1950 | F11: =F10*Inputs!$B$20 -> 19500 | G11: =G10*Inputs!$B$20 -> 195000
A12: of which paid through Apple in-app purchase | B12: =B10-B11 -> 0 | C12: =C10-C11 -> 10.5 | D12: =D10-D11 -> 105 | E12: =E10-E11 -> 1050 | F12: =F10-F11 -> 10500 | G12: =G10-G11 -> 105000
A13: Stripe fees on subscriptions | B13: =B7*Inputs!$B$20*Inputs!$B$22+B11*(Inputs!$B$21+Inputs!$B$23) -> 0 | C13: =C7*Inputs!$B$20*Inputs!$B$22+C11*(Inputs!$B$21+Inputs!$B$23) -> 1.677 | D13: =D7*Inputs!$B$20*Inputs!$B$22+D11*(Inputs!$B$21+Inputs!$B$23) -> 16.77 | E13: =E7*Inputs!$B$20*Inputs!$B$22+E11*(Inputs!$B$21+Inputs!$B$23) -> 167.7 | F13: =F7*Inputs!$B$20*Inputs!$B$22+F11*(Inputs!$B$21+Inputs!$B$23) -> 1677 | G13: =G7*Inputs!$B$20*Inputs!$B$22+G11*(Inputs!$B$21+Inputs!$B$23) -> 16770
A14: Apple fees on in-app purchases | B14: =B12*IF(B5>Inputs!$B$26,Inputs!$B$25,Inputs!$B$24) -> 0 | C14: =C12*IF(C5>Inputs!$B$26,Inputs!$B$25,Inputs!$B$24) -> 1.575 | D14: =D12*IF(D5>Inputs!$B$26,Inputs!$B$25,Inputs!$B$24) -> 15.75 | E14: =E12*IF(E5>Inputs!$B$26,Inputs!$B$25,Inputs!$B$24) -> 157.5 | F14: =F12*IF(F5>Inputs!$B$26,Inputs!$B$25,Inputs!$B$24) -> 2625 | G14: =G12*IF(G5>Inputs!$B$26,Inputs!$B$25,Inputs!$B$24) -> 26250
A15: Subscription revenue after fees | B15: =B10-B13-B14 -> 0 | C15: =C10-C13-C14 -> 26.748 | D15: =D10-D13-D14 -> 267.48 | E15: =E10-E13-E14 -> 2674.8 | F15: =F10-F13-F14 -> 25698 | G15: =G10-G13-G14 -> 256980
A16: paid out to creators | B16: =B15*Inputs!$B$27 -> 0 | C16: =C15*Inputs!$B$27 -> 18.7236 | D16: =D15*Inputs!$B$27 -> 187.236 | E16: =E15*Inputs!$B$27 -> 1872.36 | F16: =F15*Inputs!$B$27 -> 17988.6 | G16: =G15*Inputs!$B$27 -> 179886
A17: Platform subscription revenue | B17: =B15-B16 -> 0 | C17: =C15-C16 -> 8.0244 | D17: =D15-D16 -> 80.244 | E17: =E15-E16 -> 802.44 | F17: =F15-F16 -> 7709.4 | G17: =G15-G16 -> 77094
A18: Accepted human-mode requests | B18: =B5*Inputs!$B$9 -> 0 | C18: =C5*Inputs!$B$9 -> 0.5 | D18: =D5*Inputs!$B$9 -> 5 | E18: =E5*Inputs!$B$9 -> 50 | F18: =F5*Inputs!$B$9 -> 500 | G18: =G5*Inputs!$B$9 -> 5000
A19: Human-mode spend by fans (gross) | B19: =B18*Inputs!$B$10 -> 0 | C19: =C18*Inputs!$B$10 -> 7.5 | D19: =D18*Inputs!$B$10 -> 75 | E19: =E18*Inputs!$B$10 -> 750 | F19: =F18*Inputs!$B$10 -> 7500 | G19: =G18*Inputs!$B$10 -> 75000
A20: Stripe fees on human modes | B20: =B18*(Inputs!$B$21*Inputs!$B$10+Inputs!$B$22) -> 0 | C20: =C18*(Inputs!$B$21*Inputs!$B$10+Inputs!$B$22) -> 0.3675 | D20: =D18*(Inputs!$B$21*Inputs!$B$10+Inputs!$B$22) -> 3.675 | E20: =E18*(Inputs!$B$21*Inputs!$B$10+Inputs!$B$22) -> 36.75 | F20: =F18*(Inputs!$B$21*Inputs!$B$10+Inputs!$B$22) -> 367.5 | G20: =G18*(Inputs!$B$21*Inputs!$B$10+Inputs!$B$22) -> 3675
A21: paid out to creators | B21: =B19*(1-Inputs!$B$11) -> 0 | C21: =C19*(1-Inputs!$B$11) -> 6 | D21: =D19*(1-Inputs!$B$11) -> 60 | E21: =E19*(1-Inputs!$B$11) -> 600 | F21: =F19*(1-Inputs!$B$11) -> 6000 | G21: =G19*(1-Inputs!$B$11) -> 60000
A22: Platform human-mode revenue (take minus card fee) | B22: =B19*Inputs!$B$11-B20 -> 0 | C22: =C19*Inputs!$B$11-C20 -> 1.1325 | D22: =D19*Inputs!$B$11-D20 -> 11.325 | E22: =E19*Inputs!$B$11-E20 -> 113.25 | F22: =F19*Inputs!$B$11-F20 -> 1132.5 | G22: =G19*Inputs!$B$11-G20 -> 11325
A23: Ad revenue to the platform (non-paying fans only, after network share) | B23: =Inputs!$B$33*B8*Inputs!$B$34*Inputs!$B$35*Inputs!B$41/1000*(1-Inputs!$B$36) -> 0 | C23: =Inputs!$B$33*C8*Inputs!$B$34*Inputs!$B$35*Inputs!C$41/1000*(1-Inputs!$B$36) -> 2.793 | D23: =Inputs!$B$33*D8*Inputs!$B$34*Inputs!$B$35*Inputs!D$41/1000*(1-Inputs!$B$36) -> 41.895 | E23: =Inputs!$B$33*E8*Inputs!$B$34*Inputs!$B$35*Inputs!E$41/1000*(1-Inputs!$B$36) -> 558.6 | F23: =Inputs!$B$33*F8*Inputs!$B$34*Inputs!$B$35*Inputs!F$41/1000*(1-Inputs!$B$36) -> 8379 | G23: =Inputs!$B$33*G8*Inputs!$B$34*Inputs!$B$35*Inputs!G$41/1000*(1-Inputs!$B$36) -> 111720
A24: Total fan spend (gross, excluding ads) | B24: =B10+B19 -> 0 | C24: =C10+C19 -> 37.5 | D24: =D10+D19 -> 375 | E24: =E10+E19 -> 3750 | F24: =F10+F19 -> 37500 | G24: =G10+G19 -> 375000
A25: PLATFORM REVENUE | B25: =B17+B22+B23 -> 0 | C25: =C17+C22+C23 -> 11.9499 | D25: =D17+D22+D23 -> 133.464 | E25: =E17+E22+E23 -> 1474.29 | F25: =F17+F22+F23 -> 17220.9 | G25: =G17+G22+G23 -> 200139
A26: Costs
A27: AI messages per month (fans) | B27: =B5*((1-Inputs!$B$7)*Inputs!$B$13+Inputs!$B$7*Inputs!$B$14) -> 0 | C27: =C5*((1-Inputs!$B$7)*Inputs!$B$13+Inputs!$B$7*Inputs!$B$14) -> 3125 | D27: =D5*((1-Inputs!$B$7)*Inputs!$B$13+Inputs!$B$7*Inputs!$B$14) -> 31250 | E27: =E5*((1-Inputs!$B$7)*Inputs!$B$13+Inputs!$B$7*Inputs!$B$14) -> 312500 | F27: =F5*((1-Inputs!$B$7)*Inputs!$B$13+Inputs!$B$7*Inputs!$B$14) -> 3125000 | G27: =G5*((1-Inputs!$B$7)*Inputs!$B$13+Inputs!$B$7*Inputs!$B$14) -> 31250000
A28: Fan AI (model calls) | B28: =B27*Inputs!$B$12 -> 0 | C28: =C27*Inputs!$B$12 -> 43.75 | D28: =D27*Inputs!$B$12 -> 437.5 | E28: =E27*Inputs!$B$12 -> 4375 | F28: =F27*Inputs!$B$12 -> 43750 | G28: =G27*Inputs!$B$12 -> 437500
A29: Creator-side AI and verification | B29: =B6*Inputs!$B$19 -> 0 | C29: =C6*Inputs!$B$19 -> 75 | D29: =D6*Inputs!$B$19 -> 150 | E29: =E6*Inputs!$B$19 -> 1500 | F29: =F6*Inputs!$B$19 -> 15000 | G29: =G6*Inputs!$B$19 -> 150000
A30: AI voice | B30: =B5*Inputs!$B$28*Inputs!$B$29/1000*Inputs!$B$30 -> 0 | C30: =C5*Inputs!$B$28*Inputs!$B$29/1000*Inputs!$B$30 -> 1.6 | D30: =D5*Inputs!$B$28*Inputs!$B$29/1000*Inputs!$B$30 -> 16 | E30: =E5*Inputs!$B$28*Inputs!$B$29/1000*Inputs!$B$30 -> 160 | F30: =F5*Inputs!$B$28*Inputs!$B$29/1000*Inputs!$B$30 -> 1600 | G30: =G5*Inputs!$B$28*Inputs!$B$29/1000*Inputs!$B$30 -> 16000
A31: Moderation and image scanning | B31: =B5*Inputs!$B$31 -> 0 | C31: =C5*Inputs!$B$31 -> 0.2 | D31: =D5*Inputs!$B$31 -> 2 | E31: =E5*Inputs!$B$31 -> 20 | F31: =F5*Inputs!$B$31 -> 200 | G31: =G5*Inputs!$B$31 -> 2000
A32: App compute (Fargate: interactive, generation, ingestion, trust worker, web) | B32: =Inputs!B$42 -> 75 | C32: =Inputs!C$42 -> 90 | D32: =Inputs!D$42 -> 150 | E32: =Inputs!E$42 -> 550 | F32: =Inputs!F$42 -> 3200 | G32: =Inputs!G$42 -> 17000
A33: Load balancer, WAF, NAT and networking | B33: =Inputs!B$43 -> 60 | C33: =Inputs!C$43 -> 70 | D33: =Inputs!D$43 -> 90 | E33: =Inputs!E$43 -> 250 | F33: =Inputs!F$43 -> 900 | G33: =Inputs!G$43 -> 4500
A34: Postgres + pgvector (RDS, backups, replicas) | B34: =Inputs!B$44 -> 60 | C34: =Inputs!C$44 -> 60 | D34: =Inputs!D$44 -> 190 | E34: =Inputs!E$44 -> 530 | F34: =Inputs!F$44 -> 2800 | G34: =Inputs!G$44 -> 18000
A35: Redis / pub-sub (not in the design; added past one WebSocket node) | B35: =Inputs!B$45 -> 0 | C35: =Inputs!C$45 -> 0 | D35: =Inputs!D$45 -> 0 | E35: =Inputs!E$45 -> 100 | F35: =Inputs!F$45 -> 600 | G35: =Inputs!G$45 -> 2500
A36: Staging environment (separate stack, required by W8 isolation) | B36: =Inputs!B$46 -> 120 | C36: =Inputs!C$46 -> 150 | D36: =Inputs!D$46 -> 200 | E36: =Inputs!E$46 -> 500 | F36: =Inputs!F$46 -> 1500 | G36: =Inputs!G$46 -> 5000
A37: Object storage, CDN and data transfer | B37: =Inputs!B$47 -> 5 | C37: =Inputs!C$47 -> 5 | D37: =Inputs!D$47 -> 20 | E37: =Inputs!E$47 -> 200 | F37: =Inputs!F$47 -> 2000 | G37: =Inputs!G$47 -> 9000
A38: Monitoring, logs, error tracking | B38: =Inputs!B$48 -> 30 | C38: =Inputs!C$48 -> 50 | D38: =Inputs!D$48 -> 100 | E38: =Inputs!E$48 -> 400 | F38: =Inputs!F$48 -> 2500 | G38: =Inputs!G$48 -> 12000
A39: Secrets, KMS, security tooling, DR copies | B39: =Inputs!B$49 -> 10 | C39: =Inputs!C$49 -> 15 | D39: =Inputs!D$49 -> 30 | E39: =Inputs!E$49 -> 120 | F39: =Inputs!F$49 -> 700 | G39: =Inputs!G$49 -> 3500
A40: LiveKit (Ship $50 pilot; Scale $500 once calls and analytics are needed) | B40: =Inputs!B$50 -> 0 | C40: =Inputs!C$50 -> 50 | D40: =Inputs!D$50 -> 50 | E40: =Inputs!E$50 -> 500 | F40: =Inputs!F$50 -> 500 | G40: =Inputs!G$50 -> 500
A41: ElevenLabs plan floor (only after AI voice ships) | B41: =Inputs!B$51 -> 0 | C41: =Inputs!C$51 -> 0 | D41: =Inputs!D$51 -> 22 | E41: =Inputs!E$51 -> 99 | F41: =Inputs!F$51 -> 99 | G41: =Inputs!G$51 -> 299
...
